<?xml version="1.0" encoding="UTF-8"?>
<robot name="formular_car">
    <!--* Body Link  -->
    <link name="body">
        <inertial>
            <mass value="600.0"/>
            <inertia ixx="1.0" ixy="0.0" ixz="0.0" iyy="1.0" iyz="0.0" izz="1.0"/>
        </inertial>
        <visual>
            <geometry>
                <mesh filename="body.stl" scale="1.0"/>
            </geometry>
        </visual>
        <collision>
            <geometry>
                <mesh filename="body.stl" scale="1.0"/>
            </geometry>
        </collision>
    </link>

    <!--* Supension Link -->
    <link name="susp_fl">
        <inertial>
            <mass value="1e-5"/>
            <inertia ixx="1e-6" ixy="0.0" ixz="0.0" iyy="1e-6" iyz="0.0" izz="1e-6"/>
        </inertial>
    </link>

    <link name="susp_fr">
        <inertial>
            <mass value="1e-5"/>
            <inertia ixx="1e-6" ixy="0.0" ixz="0.0" iyy="1e-6" iyz="0.0" izz="1e-6"/>
        </inertial>
    </link>

    <link name="susp_rl">
        <inertial>
            <mass value="1e-5"/>
            <inertia ixx="1e-6" ixy="0.0" ixz="0.0" iyy="1e-6" iyz="0.0" izz="1e-6"/>
        </inertial>
    </link>

    <link name="susp_rr">
        <inertial>
            <mass value="1e-5"/>
            <inertia ixx="1e-6" ixy="0.0" ixz="0.0" iyy="1e-6" iyz="0.0" izz="1e-6"/>
        </inertial>
    </link>

    <!--* Steering link -->
    <link name="steering_fl">
        <inertial>
            <mass value="1e-5"/>
            <inertia ixx="1e-6" ixy="0.0" ixz="0.0" iyy="1e-6" iyz="0.0" izz="1e-6"/>
        </inertial>
    </link>

    <link name="steering_fr">
        <inertial>
            <mass value="1e-5"/>
            <inertia ixx="1e-6" ixy="0.0" ixz="0.0" iyy="1e-6" iyz="0.0" izz="1e-6"/>
        </inertial>
    </link>

    <link name="steering_rl">
        <inertial>
            <mass value="1e-5"/>
            <inertia ixx="1e-6" ixy="0.0" ixz="0.0" iyy="1e-6" iyz="0.0" izz="1e-6"/>
        </inertial>
    </link>

    <link name="steering_rr">
        <inertial>
            <mass value="1e-5"/>
            <inertia ixx="1e-6" ixy="0.0" ixz="0.0" iyy="1e-6" iyz="0.0" izz="1e-6"/>
        </inertial>
    </link>
    
    <!--* Wheel Link -->
    <link name="wheel_fl">
        <inertial>
            <mass value="10.0"/>
            <inertia ixx="1.0" ixy="0.0" ixz="0.0" iyy="1.0" iyz="0.0" izz="1.0"/>
        </inertial>
        <visual>
            <geometry>
                <mesh filename="wheel_FL.stl" scale="1.0"/>
            </geometry>
        </visual>
        <collision>
            <geometry>
                <mesh filename="wheel_FL.stl" scale="1.0"/>
            </geometry>
        </collision>
    </link>

    <link name="wheel_fr">
        <inertial>
            <mass value="10.0"/>
            <inertia ixx="1.0" ixy="0.0" ixz="0.0" iyy="1.0" iyz="0.0" izz="1.0"/>
        </inertial>
        <visual>
            <geometry>
                <mesh filename="wheel_FR.stl" scale="1.0"/>
            </geometry>
        </visual>
        <collision>
            <geometry>
                <mesh filename="wheel_FR.stl" scale="1.0"/>
            </geometry>
        </collision>
    </link>

    <link name="wheel_rl">
        <inertial>
            <mass value="10.0"/>
            <inertia ixx="1.0" ixy="0.0" ixz="0.0" iyy="1.0" iyz="0.0" izz="1.0"/>
        </inertial>
        <visual>
            <geometry>
                <mesh filename="wheel_RL.stl" scale="1.0"/>
            </geometry>
        </visual>
        <collision>
            <geometry>
                <mesh filename="wheel_RL.stl" scale="1.0"/>
            </geometry>
        </collision>
    </link>

    <link name="wheel_rr">
        <inertial>
            <mass value="10.0"/>
            <inertia ixx="1.0" ixy="0.0" ixz="0.0" iyy="1.0" iyz="0.0" izz="1.0"/>
        </inertial>
        <visual>
            <geometry>
                <mesh filename="wheel_RR.stl" scale="1.0"/>
            </geometry>
        </visual>
        <collision>
            <geometry>
                <mesh filename="wheel_RR.stl" scale="1.0"/>
            </geometry>
        </collision>
    </link>


    <!-- ======================== -->
    <!--     FRONT LEFT WHEEL     -->
    <!-- ======================== -->
    <!--* Wheel mount  -->
    <joint name="susp_joint_fl" type="prismatic">
        <origin xyz="-1.0 1.4 0.05" rpy="0.0 0.0 0.0"/>
        <parent link="body"/>
        <child link="susp_fl"/>
        <axis xyz="0.0 0.0 1.0"/>
        <limit lower="-0.1" upper="0.01" effort="500" velocity="1.0"/>
    </joint>

    <!--* Steering Joint -->
    <joint name="steer_joint_fl" type="revolute">
        <parent link="susp_fl"/>
        <child link="steering_fl"/>
        <axis xyz="0.0 0.0 1.0"/>
        <limit lower="-0.524" upper="0.524" effort="80" velocity="100"/>
    </joint>

    <!--* Wheel joint -->
    <joint name="wheel_joint_fl" type="continuous">
        <parent link="steering_fl"/>
        <child link="wheel_fl"/>
        <axis xyz="1.0 0.0 0.0"/>
    </joint>

    <!-- ========================= -->
    <!--     FRONT RIGHT WHEEL     -->
    <!-- ========================= -->
    <!--* Wheel mount  -->
    <joint name="susp_joint_fr" type="prismatic">
        <origin xyz="1.0 1.4 0.05" rpy="0.0 0.0 0.0"/>
        <parent link="body"/>
        <child link="susp_fr"/>
        <axis xyz="0.0 0.0 1.0"/>
        <limit lower="-0.1" upper="0.01" effort="500" velocity="1.0"/>
    </joint>

    <!--* Steering Joint -->
    <joint name="steer_joint_fr" type="revolute">
        <parent link="susp_fr"/>
        <child link="steering_fr"/>
        <axis xyz="0.0 0.0 1.0"/>
        <limit lower="-0.524" upper="0.524" effort="80" velocity="100"/>
    </joint>

    <!--* Wheel joint -->
    <joint name="wheel_joint_fr" type="continuous">
        <parent link="steering_fr"/>
        <child link="wheel_fr"/>
        <axis xyz="1.0 0.0 0.0"/>
    </joint>

    <!-- ======================= -->
    <!--     RESR LEFT WHEEL     -->
    <!-- ======================= -->
    <!--* Wheel mount  -->
    <joint name="susp_joint_rl" type="prismatic">
        <origin xyz="-1.05 -1.5 0.08" rpy="0.0 0.0 0.0"/>
        <parent link="body"/>
        <child link="susp_rl"/>
        <axis xyz="0.0 0.0 1.0"/>
        <limit lower="-0.1" upper="0.01" effort="500" velocity="1.0"/>
    </joint>

    <!--* Steering Joint -->
    <joint name="steer_joint_rl" type="fixed">
        <parent link="susp_rl"/>
        <child link="steering_rl"/>
    </joint>

    <!--* Wheel joint -->
    <joint name="wheel_joint_rl" type="continuous">
        <parent link="steering_rl"/>
        <child link="wheel_rl"/>
        <axis xyz="1.0 0.0 0.0"/>
    </joint>

    <!-- ======================== -->
    <!--     REAR RIGHT WHEEL     -->
    <!-- ======================== -->
    <!--* Wheel mount  -->
    <joint name="susp_joint_rr" type="prismatic">
        <origin xyz="1.05 -1.5 0.08" rpy="0.0 0.0 0.0"/>
        <parent link="body"/>
        <child link="susp_rr"/>
        <axis xyz="0.0 0.0 1.0"/>
        <limit lower="-0.1" upper="0.01" effort="500" velocity="1.0"/>
    </joint>

    <!--* Steering Joint -->
    <joint name="steer_joint_rr" type="fixed">
        <parent link="susp_rr"/>
        <child link="steering_rr"/>
    </joint>

    <!--* Wheel joint -->
    <joint name="wheel_joint_rr" type="continuous">
        <parent link="steering_rr"/>
        <child link="wheel_rr"/>
        <axis xyz="1.0 0.0 0.0"/>
    </joint>
</robot>